Workbook

Sheet Historias de Usuario
B1: Desarrollo ágil: Historias de usuario y criterios de aceptación
B2: Quality360 · Dashboard de certificación QA de historias de usuario · Capstone DuocUC — Grupo 8
B3: Leyenda: ID con prefijo F = HDU de Frontend · B = HDU de Backend. Cada HDU se desglosa en escenarios (criterios de aceptación) con formato Contexto → Evento → Resultado.
C4: Enunciado de la historia | G4: Criterios de aceptación
B5: Identificador (ID) de la historia | C5: Rol | D5: Característica / Funcionalidad | E5: Razón / Resultado | F5: Número (#) de escenario | G5: Criterio de aceptación (Título) | H5: Contexto | I5: Evento | J5: Resultado / Comportamiento esperado | K5: Epica
B6: ÉPICA 1 — ACCESO, PORTALES Y ORGANIZACIÓN QA · Autenticación, autorización por rol y ámbito, portales de inicio y administración de usuarios, roles y supervisión.
B7: E1-F01 | C7: Usuario de Quality360 | D7: Como Usuario de Quality360, quiero ingresar al portal de inicio de sesión e introducir mis credenciales | E7: Para acceder a la plataforma de forma segura | F7: 1 | G7: Formulario de ingreso | H7: El usuario accede a la pantalla de inicio de sesión. | I7: Visualiza el formulario. | J7: Se muestran los campos de correo y contraseña, con opción de mostrar u ocultar la contraseña. | K7: 1
F8: 2 | G8: Campos obligatorios | H8: El usuario deja el correo o la contraseña en blanco. | I8: Presiona Ingresar. | J8: El sistema valida los campos obligatorios y marca los que faltan sin enviar la solicitud.
F9: 3 | G9: Credenciales incorrectas | H9: El usuario ingresa credenciales válidas en formato pero incorrectas. | I9: Presiona Ingresar. | J9: Se indica que el ingreso está en proceso y luego se presenta un mensaje genérico de credenciales incorrectas, sin revelar si el correo existe.
B10: E1-F02 | C10: Quality Engineer (QE) | D10: Como Quality Engineer (QE), quiero ingresar al portal del QE después de iniciar sesión | E10: Para acceder a las funciones de supervisión de mi equipo | F10: 1 | G10: Redirección al portal QE | H10: El usuario tiene rol QE y credenciales válidas. | I10: Inicia sesión. | J10: Es dirigido a su portal, que muestra su identidad y la navegación de supervisión. | K10: 1
F11: 2 | G11: Acceso a ruta de otro rol | H11: El QE está autenticado. | I11: Intenta abrir una ruta administrativa o de analista. | J11: Se presenta acceso denegado o se redirige al portal autorizado.
F12: 3 | G12: Navegación disponible | H12: El QE está en su portal. | I12: Revisa el menú. | J12: Solo aparecen opciones de supervisión (equipo, historias supervisadas, perfil, cerrar sesión).
B13: E1-F03 | C13: Quality Engineer (QE) | D13: Como Quality Engineer (QE), quiero ver mi panel de inicio con un resumen de mis analistas e historias bajo supervisión | E13: Para identificar mi ámbito de trabajo y acceder a su seguimiento | F13: 1 | G13: Resumen con datos | H13: El QE tiene analistas e historias asignadas. | I13: Ingresa al panel de inicio. | J13: Se muestra la cantidad de analistas supervisados y de HDU bajo supervisión, con acceso a ambos listados. | K13: 1
F14: 2 | G14: Sin datos | H14: El QE no tiene analistas ni historias asignadas. | I14: Ingresa al panel de inicio. | J14: Se informa explícitamente la ausencia de datos, sin mostrar cifras ficticias.
F15: 3 | G15: Error de consulta | H15: El servicio de resumen no responde. | I15: Ingresa al panel de inicio. | J15: Se diferencia el estado de error del estado de carga y de la ausencia de datos, con opción de reintentar.
B16: E1-F04 | C16: Quality Engineer (QE) | D16: Como Quality Engineer (QE), quiero consultar el listado de analistas QA que superviso | E16: Para reconocer los integrantes de mi equipo | F16: 1 | G16: Listado vigente | H16: El QE tiene relaciones de supervisión vigentes. | I16: Abre la sección de analistas. | J16: Se muestran únicamente los analistas con supervisión vigente, identificados por nombre y correo. | K16: 1
F17: 2 | G17: Relaciones finalizadas | H17: Un analista fue reasignado a otro QE. | I17: Abre la sección de analistas. | J17: El analista reasignado no aparece en el listado.
F18: 3 | G18: Sin analistas | H18: El QE no tiene analistas asignados. | I18: Abre la sección de analistas. | J18: Se informa que no hay analistas asignados.
B19: E1-F05 | C19: Analista QA | D19: Como Analista QA, quiero ingresar al portal del QA después de iniciar sesión | E19: Para acceder a las funciones correspondientes a mi trabajo de certificación | F19: 1 | G19: Redirección al portal QA | H19: El usuario tiene rol Analista QA. | I19: Inicia sesión. | J19: Es dirigido a su portal, con su identidad y la navegación correspondiente. | K19: 1
F20: 2 | G20: Sin funciones administrativas | H20: El analista está en su portal. | I20: Revisa el menú y las rutas. | J20: No se presentan funciones administrativas ni de supervisión.
F21: 3 | G21: Ruta no autorizada | H21: El analista está autenticado. | I21: Intenta abrir una ruta de QE o Administrador. | J21: Se presenta acceso denegado o se redirige a su portal.
B22: E1-F06 | C22: Analista QA | D22: Como Analista QA, quiero ver mi panel de inicio con mi QE supervisor y un resumen de mis historias asignadas | E22: Para identificar mis responsabilidades y a quién acudir ante un impedimento | F22: 1 | G22: Panel con supervisor e historias | H22: El analista tiene QE vigente e historias asignadas. | I22: Ingresa al panel de inicio. | J22: Se muestra el nombre del QE supervisor y la cantidad de HDU asignadas, con acceso a sus historias. | K22: 1
F23: 2 | G23: Sin supervisor | H23: El analista no tiene QE vigente. | I23: Ingresa al panel de inicio. | J23: Se informa que no tiene supervisor asignado.
F24: 3 | G24: Conteo no disponible | H24: La capacidad de HDU (E2) aún no está habilitada. | I24: Ingresa al panel de inicio. | J24: El portal indica que el conteo de historias todavía no está disponible.
B25: E1-F07 | C25: Administrador | D25: Como Administrador, quiero ingresar al portal de administración después de iniciar sesión | E25: Para acceder a la configuración de usuarios y organización QA | F25: 1 | G25: Redirección al portal administrativo | H25: El usuario tiene rol Administrador. | I25: Inicia sesión. | J25: Es dirigido a su portal con los accesos administrativos habilitados. | K25: 1
F26: 2 | G26: Accesos habilitados | H26: El Administrador está en su portal. | I26: Revisa la navegación. | J26: Se presentan accesos a usuarios, roles y supervisión.
F27: 3 | G27: Sesión expirada | H27: La sesión del Administrador expiró. | I27: Intenta abrir el portal. | J27: Se le solicita iniciar sesión nuevamente.
B28: E1-F08 | C28: Administrador | D28: Como Administrador, quiero ver mi panel de inicio con accesos a usuarios, roles y relaciones de supervisión | E28: Para administrar la estructura de acceso de la plataforma | F28: 1 | G28: Panel administrativo | H28: El Administrador ingresa a su panel. | I28: Visualiza el panel. | J28: Se muestran accesos a gestión de usuarios, roles y supervisión. | K28: 1
F29: 2 | G29: Error de carga | H29: El servicio administrativo no responde. | I29: Ingresa al panel. | J29: Se informa el error de carga sin mostrar cifras ficticias.
F30: 3 | G30: Navegación directa | H30: El Administrador está en el panel. | I30: Selecciona un acceso. | J30: Se abre la pantalla correspondiente.
B31: E1-F09 | C31: Administrador | D31: Como Administrador, quiero utilizar una pantalla para registrar usuarios, actualizar sus datos, asignar su rol y activar o desactivar su acceso | E31: Para mantener vigente el acceso de los participantes | F31: 1 | G31: Listar y buscar | H31: Existen usuarios registrados. | I31: Abre la pantalla de usuarios y busca por nombre o correo. | J31: Se listan los usuarios y el buscador filtra los resultados. | K31: 1
F32: 2 | G32: Validación de datos | H32: El Administrador registra un usuario con datos incompletos. | I32: Guarda el formulario. | J32: Se validan los datos obligatorios y se indican los errores.
F33: 3 | G33: Confirmación de cambios sensibles | H33: El Administrador desactiva un usuario o cambia su rol. | I33: Confirma la operación. | J33: Se solicita confirmación previa y se muestra el resultado de la operación.
B34: E1-F10 | C34: Administrador | D34: Como Administrador, quiero utilizar una pantalla para asignar o cambiar el QE supervisor de un analista QA | E34: Para mantener actualizada la organización del equipo | F34: 1 | G34: Selección de analista y QE | H34: Existen analistas y QE activos. | I34: Selecciona un analista y un QE. | J34: Se muestra la relación vigente del analista antes de confirmar. | K34: 1
F35: 2 | G35: Motivo del cambio | H35: El analista ya tiene un QE vigente. | I35: Asigna un nuevo QE. | J35: Se solicita el motivo del cambio antes de guardar.
F36: 3 | G36: Historial de supervisión | H36: El analista ha tenido varios supervisores. | I36: Consulta el historial. | J36: Se muestran las relaciones anteriores con fechas y motivos.
B37: E1-F11 | C37: Usuario autenticado | D37: Como Usuario autenticado, quiero consultar mi nombre, correo y rol en la plataforma | E37: Para verificar con qué identidad y permisos estoy trabajando | F37: 1 | G37: Datos del perfil | H37: El usuario está autenticado. | I37: Abre su perfil. | J37: Se muestran su nombre, correo y rol. | K37: 1
F38: 2 | G38: Rol de solo lectura | H38: El usuario está en su perfil. | I38: Intenta modificar el rol. | J38: El rol no es editable desde el perfil personal.
F39: 3 | G39: Datos actualizados | H39: El Administrador cambió el rol del usuario. | I39: El usuario vuelve a abrir su perfil. | J39: Se refleja el rol vigente.
B40: E1-F12 | C40: Usuario autenticado | D40: Como Usuario autenticado, quiero cerrar sesión desde mi portal | E40: Para finalizar mi acceso a la plataforma | F40: 1 | G40: Opción visible | H40: El usuario está en su portal. | I40: Busca la opción de salir. | J40: La opción de cerrar sesión es visible desde cualquier pantalla. | K40: 1
...

Sheet Épicas
B1: Quality360 · Épicas del producto
B2: Resumen de épicas y cantidad de HDU. Los conteos se calculan desde la hoja Historias de Usuario.
B4: Épica | C4: Nombre | D4: Descripción | E4: HDU Frontend | F4: HDU Backend | G4: Total HDU
B5: 1 | C5: Acceso, portales y organización QA | D5: Autenticación, autorización por rol y ámbito, portales de inicio y administración de usuarios, roles y supervisión. | E5: =COUNTIF('Historias de Usuario'!$B:$B,"E1-F*") -> 12 | F5: =COUNTIF('Historias de Usuario'!$B:$B,"E1-B*") -> 12 | G5: =E5+F5 -> 24
B6: 2 | C6: Gestión de historias de usuario (HDU) | D6: Registro, asignación, estados y consulta de las HDU bajo certificación, organizadas por célula y sprint. | E6: =COUNTIF('Historias de Usuario'!$B:$B,"E2-F*") -> 4 | F6: =COUNTIF('Historias de Usuario'!$B:$B,"E2-B*") -> 4 | G6: =E6+F6 -> 8
B7: 3 | C7: Certificación y entregables | D7: Checklist de 10 entregables con trazabilidad (quién/cuándo), evidencias y generación del certificado de cierre. | E7: =COUNTIF('Historias de Usuario'!$B:$B,"E3-F*") -> 4 | F7: =COUNTIF('Historias de Usuario'!$B:$B,"E3-B*") -> 4 | G7: =E7+F7 -> 8
B8: 4 | C8: Impedimentos y riesgos | D8: Registro, seguimiento y resolución de impedimentos; clasificación del nivel de riesgo de cada HDU. | E8: =COUNTIF('Historias de Usuario'!$B:$B,"E4-F*") -> 4 | F8: =COUNTIF('Historias de Usuario'!$B:$B,"E4-B*") -> 4 | G8: =E8+F8 -> 8
B9: 5 | C9: Integración con Jira Cloud | D9: Sincronización de lectura de HDU desde Jira Cloud e importación alternativa por CSV/JSON. | E9: =COUNTIF('Historias de Usuario'!$B:$B,"E5-F*") -> 4 | F9: =COUNTIF('Historias de Usuario'!$B:$B,"E5-B*") -> 4 | G9: =E9+F9 -> 8
B10: 6 | C10: Indicadores y dashboards | D10: Dashboards de cumplimiento, avance, riesgos, impedimentos y carga de trabajo para la supervisión del QE. | E10: =COUNTIF('Historias de Usuario'!$B:$B,"E6-F*") -> 4 | F10: =COUNTIF('Historias de Usuario'!$B:$B,"E6-B*") -> 4 | G10: =E10+F10 -> 8
B11: Total | E11: =SUM(E5:E10) -> 32 | F11: =SUM(F5:F10) -> 32 | G11: =SUM(G5:G10) -> 64

Sheet Relación Front-Back
B1: Relación entre HDU de Frontend y Backend
B2: Cada funcionalidad visible por el usuario se sostiene en las reglas de backend que la hacen posible.
B4: Épica | C4: Funcionalidad | D4: HDU Frontend | E4: HDU Backend
B5: E1 | C5: Inicio de sesión | D5: E1-F01 | E5: E1-B01, E1-B02
C6: Portal e inicio del QE | D6: E1-F02, E1-F03 | E6: E1-B02, E1-B03
C7: Equipo supervisado | D7: E1-F04 | E7: E1-B04
C8: Portal e inicio del QA | D8: E1-F05, E1-F06 | E8: E1-B02, E1-B05
C9: Portal e inicio administrativo | D9: E1-F07, E1-F08 | E9: E1-B02, E1-B06
C10: Usuarios y roles | D10: E1-F09 | E10: E1-B07, E1-B08, E1-B12
C11: Supervisión | D11: E1-F10 | E11: E1-B09, E1-B12
C12: Perfil | D12: E1-F11 | E12: E1-B10
C13: Cierre de sesión | D13: E1-F12 | E13: E1-B11
B15: E2 | C15: Registro de HDU | D15: E2-F01 | E15: E2-B01
C16: Asignación de analista | D16: E2-F02 | E16: E2-B03, E2-B04
C17: Listado y filtros | D17: E2-F03 | E17: E2-B03
C18: Detalle y estados | D18: E2-F04 | E18: E2-B02, E2-B04
B20: E3 | C20: Checklist de entregables | D20: E3-F01, E3-F02 | E20: E3-B01, E3-B02
C21: Aprobación del QE | D21: E3-F03 | E21: E3-B02, E3-B04
C22: Certificado | D22: E3-F04 | E22: E3-B03, E3-B04
B24: E4 | C24: Registro de impedimentos | D24: E4-F01 | E24: E4-B01
C25: Gestión de impedimentos | D25: E4-F02, E4-F03 | E25: E4-B02, E4-B04
C26: Nivel de riesgo | D26: E4-F04 | E26: E4-B03, E4-B04
B28: E5 | C28: Configuración Jira | D28: E5-F01 | E28: E5-B01
C29: Sincronización Jira | D29: E5-F02 | E29: E5-B02, E5-B04
C30: Importación CSV/JSON | D30: E5-F03 | E30: E5-B03, E5-B04
C31: Historial de integración | D31: E5-F04 | E31: E5-B04
B33: E6 | C33: Dashboard de cumplimiento | D33: E6-F01 | E33: E6-B01
C34: Semáforo y carga | D34: E6-F02, E6-F03 | E34: E6-B02
C35: Tendencia y exportación | D35: E6-F04 | E35: E6-B03, E6-B04

Sheet Instructivo
B1: Historias de usuario y criterios de aceptación: Instructivo
B4: Columna | C4: Instrucciones
B5: Identificador (ID) de la historia | C5: Código que identifica unívocamente a la historia en el proyecto que se esté desarrollando. El formato debe ser elegido por el equipo.
B6: Rol | C6: Es el rol que está desempeñando el usuario cuando utiliza la funcionalidad que se está describiendo. Debe ser lo más especifico posible, describiendo el rol o actor que se está desempeñando. El enunciado puede escribirse como se sigue: Yo como un [Rol], desempeñando el rol de [Rol], como un [Rol], entre otros. Por ejemplo: Yo como cliente registrado. Desempeñando el rol de cliente registrado. Como un cliente registrado.
B7: Característica / Funcionalidad | C7: Representa la función que el rol quiere o necesita hacer en el sistema que se está desarrollando. Puede diferenciarse entre acciones obligatorias u opcionales, utilizando la palabra puede o necesita para describir la acción. Por ejemplo: Necesito realizar búsquedas de productos por categorías. Puedo seleccionar una categoría para ver el número de productos que tiene asociado.
B8: Razón / Resultado | C8: Lo que el rol necesita lograr al ejecutar la acción. Este es el resultado de ejecutar la acción desde el punto de vista del rol. Este punto puede ser opcional, pues la historia puede documentarse sólo con la definición del rol y la acción (sin definir la consecuencia).
B9: Número (#) de escenario | C9: Número (ejemplo 1, 2, 3 ó 4), que identifica al escenario asociado a la historia.
B10: Criterio de aceptación (título) | C10: Describe el contexto del escenario que define un comportamiento. Por ejemplo, si se toma el ejemplo de búsquedas de productos por categoría, un posible ejemplo pudiera ser: Categoría sin productos asociados.
B11: Contexto | C11: Proporciona mayor descripción sobre las condiciones que desencadenan el escenario.
B12: Evento | C12: Representa la acción que el usuario ejecuta, en el contexto definido para el escenario.
B13: Resultado / Comportamiento esperado | C13: Dado el contexto y la acción ejecutada por el usuario, la consecuencia es el comportamiento del sistema en esa situación.
B14: Epica | C14: Número de la épica a la que pertenece la historia. Ver hoja Épicas para nombre y descripción de cada una.
